Workbook
Name NativeTimeline_Fecha: #N/A
Name NativeTimeline_Fecha_Préstamo: #N/A
Name NativeTimeline_Fecha1: #N/A
Name SegmentaciónDeDatos_Días_Retraso_Reportados: #N/A
Name SegmentaciónDeDatos_Fp: #N/A
Name SegmentaciónDeDatos_Fp1: #N/A

Sheet Inventario_Libros
A1: ID Libro | B1: Título | C1: Autor | D1: Categoría | E1: Año Publicación | F1: Número de Copias | G1: Estantería | H1: Estado
A2: LB1001 | B2: La Odisea | C2: Homero | D2: Clásicos | E2: 2019 | F2: 1 | G2: Est-1 | H2: Activo
A3: LB1002 | B3: El Amor En Los Tiempos Del Cólera | C3: Gabriel García Márquez | D3: Novela | E3: 1936 | F3: 1 | G3: Est-1 | H3: Activo
A4: LB1003 | B4: Sobre La Felicidad | C4: Lucio Anneo Séneca | D4: Filosofía Y Pensamiento | E4: 1903 | F4: 1 | G4: A-1 | H4: Activo
A5: LB1004 | B5: Macbeth | C5: William Shakespeare | D5: Clásicos | E5: 1955 | F5: 0 | G5: Est-1 | H5: Activo
A6: LB1005 | B6: Hamlet | C6: William Shakespeare | D6: Clásicos | E6: 1905 | F6: 1 | G6: B-2 | H6: Activo
A7: LB1006 | B7: La Sombra Del Viento | C7: Carlos Ruiz Zafón | D7: Misterio | E7: 1923 | F7: 2 | G7: B-2 | H7: Retirado
A8: LB1007 | B8: Ficciones | C8: Jorge Luis Borges | D8: Cuentos / Fantasía Metafísica | E8: 1938 | F8: 0 | G8: A-1 | H8: Retirado
A9: LB1008 | B9: Ficciones | C9: Jorge Luis Borges | D9: Cuentos / Fantasía Metafísica | E9: 1997 | F9: 2 | G9: B-2 | H9: Activo
A10: LB1009 | B10: El Aleph | C10: Jorge Luis Borges | D10: Cuentos / Fantasía Metafísica | E10: 1903 | F10: 0 | G10: A-1 | H10: Retirado
A11: LB1010 | B11: La Odisea | C11: Homero | D11: Clásicos | E11: 2021 | F11: 0 | G11: A-1 | H11: Activo
A12: LB1011 | B12: La Iliada | C12: Homero | D12: Clásicos | E12: 1947 | F12: 2 | G12: A-1 | H12: Activo
A13: LB1012 | B13: La Odisea | C13: Homero | D13: Clásicos | E13: 2015 | F13: 1 | G13: Est-1 | H13: Activo
... A201: LB1200 | B201: La Casa De Los Espíritus | C201: Isabel Allende | D201: Novela | E201: 1995 | F201: 1 | G201: B-2 | H201: Retirado

Sheet Prestamos
A1: ID Préstamo | B1: Fecha Préstamo | C1: Fecha Devolución | D1: ID Libro | E1: Nombre Usuario | F1: Tipo Usuario | G1: Estado Préstamo | H1: Días Retraso Reportados | I1: Título | J1: Autor | K1: Categoría | L1: Año Publicación | M1: Estantería | N1: Estado
A2: Pr2098 | B2: 45985 | C2: No Asignado | D2: Lb1042 | E2: Jorge Ibáñez | F2: Otros | G2: Devuelto | H2: 1 | I2: =IFERROR(VLOOKUP(Prestamos[[#This Row],[ID Libro]],Inventario_Libros!A:B,2,0),"Libro No Existe") -> El Aleph | J2: =IFERROR(VLOOKUP(Prestamos[[#This Row],[ID Libro]],Inventario_Libros!A:C,3,0),"Libro No Existe") -> Jorge Luis Borges | K2: =IFERROR(VLOOKUP(Prestamos[[#This Row],[ID Libro]],Inventario_Libros!A:D,4,0),"Libro No Existe") -> Cuentos / Fantasía Metafísica | L2: =IFERROR(VLOOKUP(Prestamos[[#This Row],[ID Libro]],Inventario_Libros!A:E,5,0),"Libro No Existe") -> 1941 | M2: =_xlfn.XLOOKUP(D:D,Inventario_Libros!A:A,Inventario_Libros!G:G,"No Existe",0) -> Est-1 | N2: =IFERROR(VLOOKUP(Prestamos[[#This Row],[ID Libro]],Inventario_Libros!A:H,8,0),"Libro No Existe") -> Activo
A3: Pr2558 | B3: 45983 | C3: 46003 | D3: Lb1098 | E3: Valentina Mora | F3: Otros | G3: Retrasado | H3: 5 | I3: =IFERROR(VLOOKUP(Prestamos[[#This Row],[ID Libro]],Inventario_Libros!A:B,2,0),"Libro No Existe") -> Ficciones | J3: =IFERROR(VLOOKUP(Prestamos[[#This Row],[ID Libro]],Inventario_Libros!A:C,3,0),"Libro No Existe") -> Jorge Luis Borges | K3: =IFERROR(VLOOKUP(Prestamos[[#This Row],[ID Libro]],Inventario_Libros!A:D,4,0),"Libro No Existe") -> Cuentos / Fantasía Metafísica | L3: =IFERROR(VLOOKUP(Prestamos[[#This Row],[ID Libro]],Inventario_Libros!A:E,5,0),"Libro No Existe") -> 1990 | M3: =_xlfn.XLOOKUP(D:D,Inventario_Libros!A:A,Inventario_Libros!G:G,"No Existe",0) -> A-1 | N3: =IFERROR(VLOOKUP(Prestamos[[#This Row],[ID Libro]],Inventario_Libros!A:H,8,0),"Libro No Existe") -> Retirado
A4: Pr2009 | B4: 45982 | C4: No Asignado | D4: Lb1058 | E4: Noelia Martín | F4: Estudiante | G4: Devuelto | H4: 1 | I4: =IFERROR(VLOOKUP(Prestamos[[#This Row],[ID Libro]],Inventario_Libros!A:B,2,0),"Libro No Existe") -> Crónica De Una Muerte Anunciada | J4: =IFERROR(VLOOKUP(Prestamos[[#This Row],[ID Libro]],Inventario_Libros!A:C,3,0),"Libro No Existe") -> Gabriel García Márquez | K4: =IFERROR(VLOOKUP(Prestamos[[#This Row],[ID Libro]],Inventario_Libros!A:D,4,0),"Libro No Existe") -> Novela | L4: =IFERROR(VLOOKUP(Prestamos[[#This Row],[ID Libro]],Inventario_Libros!A:E,5,0),"Libro No Existe") -> 1929 | M4: =_xlfn.XLOOKUP(D:D,Inventario_Libros!A:A,Inventario_Libros!G:G,"No Existe",0) -> Est-1 | N4: =IFERROR(VLOOKUP(Prestamos[[#This Row],[ID Libro]],Inventario_Libros!A:H,8,0),"Libro No Existe") -> Activo
A5: Pr2233 | B5: 45981 | C5: No Asignado | D5: Lb1177 | E5: Andrés Gómez | F5: Otros | G5: Retrasado | H5: 7 | I5: =IFERROR(VLOOKUP(Prestamos[[#This Row],[ID Libro]],Inventario_Libros!A:B,2,0),"Libro No Existe") -> Matadero Cinco | J5: =IFERROR(VLOOKUP(Prestamos[[#This Row],[ID Libro]],Inventario_Libros!A:C,3,0),"Libro No Existe") -> Kurt Vonnegut | K5: =IFERROR(VLOOKUP(Prestamos[[#This Row],[ID Libro]],Inventario_Libros!A:D,4,0),"Libro No Existe") -> Ciencia Ficción | L5: =IFERROR(VLOOKUP(Prestamos[[#This Row],[ID Libro]],Inventario_Libros!A:E,5,0),"Libro No Existe") -> 1984 | M5: =_xlfn.XLOOKUP(D:D,Inventario_Libros!A:A,Inventario_Libros!G:G,"No Existe",0) -> A-1 | N5: =IFERROR(VLOOKUP(Prestamos[[#This Row],[ID Libro]],Inventario_Libros!A:H,8,0),"Libro No Existe") -> Retirado
A6: Pr2255 | B6: 45980 | C6: No Asignado | D6: Lb1059 | E6: Jorge Ibáñez | F6: Universidad | G6: Devuelto | H6: 1 | I6: =IFERROR(VLOOKUP(Prestamos[[#This Row],[ID Libro]],Inventario_Libros!A:B,2,0),"Libro No Existe") -> La Ciudad Y Los Perros | J6: =IFERROR(VLOOKUP(Prestamos[[#This Row],[ID Libro]],Inventario_Libros!A:C,3,0),"Libro No Existe") -> Mario Vargas Llosa | K6: =IFERROR(VLOOKUP(Prestamos[[#This Row],[ID Libro]],Inventario_Libros!A:D,4,0),"Libro No Existe") -> Novela | L6: =IFERROR(VLOOKUP(Prestamos[[#This Row],[ID Libro]],Inventario_Libros!A:E,5,0),"Libro No Existe") -> 1891 | M6: =_xlfn.XLOOKUP(D:D,Inventario_Libros!A:A,Inventario_Libros!G:G,"No Existe",0) -> Est-1 | N6: =IFERROR(VLOOKUP(Prestamos[[#This Row],[ID Libro]],Inventario_Libros!A:H,8,0),"Libro No Existe") -> Retirado
A7: Pr2579 | B7: 45979 | C7: No Asignado | D7: Lb1160 | E7: Camila Álvarez | F7: Universidad | G7: Devuelto | H7: 1 | I7: =IFERROR(VLOOKUP(Prestamos[[#This Row],[ID Libro]],Inventario_Libros!A:B,2,0),"Libro No Existe") -> Matar A Un Ruiseñor | J7: =IFERROR(VLOOKUP(Prestamos[[#This Row],[ID Libro]],Inventario_Libros!A:C,3,0),"Libro No Existe") -> Harper Lee | K7: =IFERROR(VLOOKUP(Prestamos[[#This Row],[ID Libro]],Inventario_Libros!A:D,4,0),"Libro No Existe") -> Novela | L7: =IFERROR(VLOOKUP(Prestamos[[#This Row],[ID Libro]],Inventario_Libros!A:E,5,0),"Libro No Existe") -> 1967 | M7: =_xlfn.XLOOKUP(D:D,Inventario_Libros!A:A,Inventario_Libros!G:G,"No Existe",0) -> C-3 | N7: =IFERROR(VLOOKUP(Prestamos[[#This Row],[ID Libro]],Inventario_Libros!A:H,8,0),"Libro No Existe") -> Activo
A8: Pr2222 | B8: 45977 | C8: 45997 | D8: Lb1016 | E8: Carlos Ruiz | F8: Estudiante | G8: Retrasado | H8: 5 | I8: =IFERROR(VLOOKUP(Prestamos[[#This Row],[ID Libro]],Inventario_Libros!A:B,2,0),"Libro No Existe") -> La Tregua | J8: =IFERROR(VLOOKUP(Prestamos[[#This Row],[ID Libro]],Inventario_Libros!A:C,3,0),"Libro No Existe") -> Mario Benedetti | K8: =IFERROR(VLOOKUP(Prestamos[[#This Row],[ID Libro]],Inventario_Libros!A:D,4,0),"Libro No Existe") -> Novela | L8: =IFERROR(VLOOKUP(Prestamos[[#This Row],[ID Libro]],Inventario_Libros!A:E,5,0),"Libro No Existe") -> 2004 | M8: =_xlfn.XLOOKUP(D:D,Inventario_Libros!A:A,Inventario_Libros!G:G,"No Existe",0) -> Est-1 | N8: =IFERROR(VLOOKUP(Prestamos[[#This Row],[ID Libro]],Inventario_Libros!A:H,8,0),"Libro No Existe") -> Retirado
A9: Pr2415 | B9: 45974 | C9: No Asignado | D9: Lb1007 | E9: Diego Gómez | F9: Adulto | G9: Devuelto | H9: 1 | I9: =IFERROR(VLOOKUP(Prestamos[[#This Row],[ID Libro]],Inventario_Libros!A:B,2,0),"Libro No Existe") -> Ficciones | J9: =IFERROR(VLOOKUP(Prestamos[[#This Row],[ID Libro]],Inventario_Libros!A:C,3,0),"Libro No Existe") -> Jorge Luis Borges | K9: =IFERROR(VLOOKUP(Prestamos[[#This Row],[ID Libro]],Inventario_Libros!A:D,4,0),"Libro No Existe") -> Cuentos / Fantasía Metafísica | L9: =IFERROR(VLOOKUP(Prestamos[[#This Row],[ID Libro]],Inventario_Libros!A:E,5,0),"Libro No Existe") -> 1938 | M9: =_xlfn.XLOOKUP(D:D,Inventario_Libros!A:A,Inventario_Libros!G:G,"No Existe",0) -> A-1 | N9: =IFERROR(VLOOKUP(Prestamos[[#This Row],[ID Libro]],Inventario_Libros!A:H,8,0),"Libro No Existe") -> Retirado
A10: Pr2290 | B10: 45973 | C10: No Asignado | D10: Lb1070 | E10: Luisa Fernández | F10: Adulto | G10: Devuelto | H10: 1 | I10: =IFERROR(VLOOKUP(Prestamos[[#This Row],[ID Libro]],Inventario_Libros!A:B,2,0),"Libro No Existe") -> La Iliada | J10: =IFERROR(VLOOKUP(Prestamos[[#This Row],[ID Libro]],Inventario_Libros!A:C,3,0),"Libro No Existe") -> Homero | K10: =IFERROR(VLOOKUP(Prestamos[[#This Row],[ID Libro]],Inventario_Libros!A:D,4,0),"Libro No Existe") -> Clásicos | L10: =IFERROR(VLOOKUP(Prestamos[[#This Row],[ID Libro]],Inventario_Libros!A:E,5,0),"Libro No Existe") -> 1993 | M10: =_xlfn.XLOOKUP(D:D,Inventario_Libros!A:A,Inventario_Libros!G:G,"No Existe",0) -> A-1 | N10: =IFERROR(VLOOKUP(Prestamos[[#This Row],[ID Libro]],Inventario_Libros!A:H,8,0),"Libro No Existe") -> Retirado
A11: Pr2045 | B11: 45971 | C11: No Asignado | D11: Lb1096 | E11: Andrés Díaz | F11: Adulto | G11: Retrasado | H11: 7 | I11: =IFERROR(VLOOKUP(Prestamos[[#This Row],[ID Libro]],Inventario_Libros!A:B,2,0),"Libro No Existe") -> Orgullo Y Prejuicio | J11: =IFERROR(VLOOKUP(Prestamos[[#This Row],[ID Libro]],Inventario_Libros!A:C,3,0),"Libro No Existe") -> Jane Austen | K11: =IFERROR(VLOOKUP(Prestamos[[#This Row],[ID Libro]],Inventario_Libros!A:D,4,0),"Libro No Existe") -> Novela | L11: =IFERROR(VLOOKUP(Prestamos[[#This Row],[ID Libro]],Inventario_Libros!A:E,5,0),"Libro No Existe") -> 2013 | M11: =_xlfn.XLOOKUP(D:D,Inventario_Libros!A:A,Inventario_Libros!G:G,"No Existe",0) -> Est-1 | N11: =IFERROR(VLOOKUP(Prestamos[[#This Row],[ID Libro]],Inventario_Libros!A:H,8,0),"Libro No Existe") -> Activo
A12: Pr2099 | B12: 45965 | C12: No Asignado | D12: Lb1151 | E12: Ana Gómez | F12: Adulto | G12: Devuelto | H12: 1 | I12: =IFERROR(VLOOKUP(Prestamos[[#This Row],[ID Libro]],Inventario_Libros!A:B,2,0),"Libro No Existe") -> El Principito | J12: =IFERROR(VLOOKUP(Prestamos[[#This Row],[ID Libro]],Inventario_Libros!A:C,3,0),"Libro No Existe") -> Antoine De Saint-Exupéry | K12: =IFERROR(VLOOKUP(Prestamos[[#This Row],[ID Libro]],Inventario_Libros!A:D,4,0),"Libro No Existe") -> Literatura Infantil / Fábula Filosófica | L12: =IFERROR(VLOOKUP(Prestamos[[#This Row],[ID Libro]],Inventario_Libros!A:E,5,0),"Libro No Existe") -> 1980 | M12: =_xlfn.XLOOKUP(D:D,Inventario_Libros!A:A,Inventario_Libros!G:G,"No Existe",0) -> Est-1 | N12: =IFERROR(VLOOKUP(Prestamos[[#This Row],[ID Libro]],Inventario_Libros!A:H,8,0),"Libro No Existe") -> Retirado
A13: Pr2243 | B13: 45963 | C13: No Asignado | D13: Lb1096 | E13: Diego Gómez | F13: Adulto | G13: Devuelto | H13: 0 | I13: =IFERROR(VLOOKUP(Prestamos[[#This Row],[ID Libro]],Inventario_Libros!A:B,2,0),"Libro No Existe") -> Orgullo Y Prejuicio | J13: =IFERROR(VLOOKUP(Prestamos[[#This Row],[ID Libro]],Inventario_Libros!A:C,3,0),"Libro No Existe") -> Jane Austen | K13: =IFERROR(VLOOKUP(Prestamos[[#This Row],[ID Libro]],Inventario_Libros!A:D,4,0),"Libro No Existe") -> Novela | L13: =IFERROR(VLOOKUP(Prestamos[[#This Row],[ID Libro]],Inventario_Libros!A:E,5,0),"Libro No Existe") -> 2013 | M13: =_xlfn.XLOOKUP(D:D,Inventario_Libros!A:A,Inventario_Libros!G:G,"No Existe",0) -> Est-1 | N13: =IFERROR(VLOOKUP(Prestamos[[#This Row],[ID Libro]],Inventario_Libros!A:H,8,0),"Libro No Existe") -> Activo
A14: Pr2323 | B14: 45962 | C14: No Asignado | D14: Lb1020 | E14: Noelia Martín | F14: Universidad | G14: Retrasado | H14: 7 | I14: =IFERROR(VLOOKUP(Prestamos[[#This Row],[ID Libro]],Inventario_Libros!A:B,2,0),"Libro No Existe") -> Rebelión En La Granja | J14: =IFERROR(VLOOKUP(Prestamos[[#This Row],[ID Libro]],Inventario_Libros!A:C,3,0),"Libro No Existe") -> George Orwell | K14: =IFERROR(VLOOKUP(Prestamos[[#This Row],[ID Libro]],Inventario_Libros!A:D,4,0),"Libro No Existe") -> Ciencia Ficción | L14: =IFERROR(VLOOKUP(Prestamos[[#This Row],[ID Libro]],Inventario_Libros!A:E,5,0),"Libro No Existe") -> 1996 | M14: =_xlfn.XLOOKUP(D:D,Inventario_Libros!A:A,Inventario_Libros!G:G,"No Existe",0) -> C-3 | N14: =IFERROR(VLOOKUP(Prestamos[[#This Row],[ID Libro]],Inventario_Libros!A:H,8,0),"Libro No Existe") -> Retirado
A15: Pr2332 | B15: 45954 | C15: 45971 | D15: Lb1199 | E15: Luisa Fernández | F15: Otros | G15: Retrasado | H15: 2 | I15: =IFERROR(VLOOKUP(Prestamos[[#This Row],[ID Libro]],Inventario_Libros!A:B,2,0),"Libro No Existe") -> La Iliada | J15: =IFERROR(VLOOKUP(Prestamos[[#This Row],[ID Libro]],Inventario_Libros!A:C,3,0),"Libro No Existe") -> Homero | K15: =IFERROR(VLOOKUP(Prestamos[[#This Row],[ID Libro]],Inventario_Libros!A:D,4,0),"Libro No Existe") -> Clásicos | L15: =IFERROR(VLOOKUP(Prestamos[[#This Row],[ID Libro]],Inventario_Libros!A:E,5,0),"Libro No Existe") -> 1968 | M15: =_xlfn.XLOOKUP(D:D,Inventario_Libros!A:A,Inventario_Libros!G:G,"No Existe",0) -> A-1 | N15: =IFERROR(VLOOKUP(Prestamos[[#This Row],[ID Libro]],Inventario_Libros!A:H,8,0),"Libro No Existe") -> Activo
A16: Pr2021 | B16: 45952 | C16: No Asignado | D16: Lb1099 | E16: Andrés Díaz | F16: Universidad | G16: Retrasado | H16: 7 | I16: =IFERROR(VLOOKUP(Prestamos[[#This Row],[ID Libro]],Inventario_Libros!A:B,2,0),"Libro No Existe") -> Matadero Cinco | J16: =IFERROR(VLOOKUP(Prestamos[[#This Row],[ID Libro]],Inventario_Libros!A:C,3,0),"Libro No Existe") -> Kurt Vonnegut | K16: =IFERROR(VLOOKUP(Prestamos[[#This Row],[ID Libro]],Inventario_Libros!A:D,4,0),"Libro No Existe") -> Ciencia Ficción | L16: =IFERROR(VLOOKUP(Prestamos[[#This Row],[ID Libro]],Inventario_Libros!A:E,5,0),"Libro No Existe") -> 1989 | M16: =_xlfn.XLOOKUP(D:D,Inventario_Libros!A:A,Inventario_Libros!G:G,"No Existe",0) -> B-2 | N16: =IFERROR(VLOOKUP(Prestamos[[#This Row],[ID Libro]],Inventario_Libros!A:H,8,0),"Libro No Existe") -> Retirado
A17: Pr2324 | B17: 45952 | C17: 45968 | D17: Lb1148 | E17: Laura Ruiz | F17: Adulto | G17: Retrasado | H17: 1 | I17: =IFERROR(VLOOKUP(Prestamos[[#This Row],[ID Libro]],Inventario_Libros!A:B,2,0),"Libro No Existe") -> Rebelión En La Granja | J17: =IFERROR(VLOOKUP(Prestamos[[#This Row],[ID Libro]],Inventario_Libros!A:C,3,0),"Libro No Existe") -> George Orwell | K17: =IFERROR(VLOOKUP(Prestamos[[#This Row],[ID Libro]],Inventario_Libros!A:D,4,0),"Libro No Existe") -> Ciencia Ficción | L17: =IFERROR(VLOOKUP(Prestamos[[#This Row],[ID Libro]],Inventario_Libros!A:E,5,0),"Libro No Existe") -> 1986 | M17: =_xlfn.XLOOKUP(D:D,Inventario_Libros!A:A,Inventario_Libros!G:G,"No Existe",0) -> Est-1 | N17: =IFERROR(VLOOKUP(Prestamos[[#This Row],[ID Libro]],Inventario_Libros!A:H,8,0),"Libro No Existe") -> Retirado
A18: Pr2554 | B18: 45951 | C18: No Asignado | D18: Lb1139 | E18: Laura Ruiz | F18: Adulto | G18: Devuelto | H18: 1 | I18: =IFERROR(VLOOKUP(Prestamos[[#This Row],[ID Libro]],Inventario_Libros!A:B,2,0),"Libro No Existe") -> La Casa De Los Espíritus | J18: =IFERROR(VLOOKUP(Prestamos[[#This Row],[ID Libro]],Inventario_Libros!A:C,3,0),"Libro No Existe") -> Isabel Allende | K18: =IFERROR(VLOOKUP(Prestamos[[#This Row],[ID Libro]],Inventario_Libros!A:D,4,0),"Libro No Existe") -> Novela | L18: =IFERROR(VLOOKUP(Prestamos[[#This Row],[ID Libro]],Inventario_Libros!A:E,5,0),"Libro No Existe") -> 2023 | M18: =_xlfn.XLOOKUP(D:D,Inventario_Libros!A:A,Inventario_Libros!G:G,"No Existe",0) -> B-2 | N18: =IFERROR(VLOOKUP(Prestamos[[#This Row],[ID Libro]],Inventario_Libros!A:H,8,0),"Libro No Existe") -> Retirado
A19: Pr2582 | B19: 45950 | C19: No Asignado | D19: Lb1003 | E19: Felipe Ramírez | F19: Adulto | G19: Devuelto | H19: 1 | I19: =IFERROR(VLOOKUP(Prestamos[[#This Row],[ID Libro]],Inventario_Libros!A:B,2,0),"Libro No Existe") -> Sobre La Felicidad | J19: =IFERROR(VLOOKUP(Prestamos[[#This Row],[ID Libro]],Inventario_Libros!A:C,3,0),"Libro No Existe") -> Lucio Anneo Séneca | K19: =IFERROR(VLOOKUP(Prestamos[[#This Row],[ID Libro]],Inventario_Libros!A:D,4,0),"Libro No Existe") -> Filosofía Y Pensamiento | L19: =IFERROR(VLOOKUP(Prestamos[[#This Row],[ID Libro]],Inventario_Libros!A:E,5,0),"Libro No Existe") -> 1903 | M19: =_xlfn.XLOOKUP(D:D,Inventario_Libros!A:A,Inventario_Libros!G:G,"No Existe",0) -> A-1 | N19: =IFERROR(VLOOKUP(Prestamos[[#This Row],[ID Libro]],Inventario_Libros!A:H,8,0),"Libro No Existe") -> Activo
A20: Pr2174 | B20: 45947 | C20: No Asignado | D20: Lb1014 | E20: Laura Ruiz | F20: Estudiante | G20: Retrasado | H20: 7 | I20: =IFERROR(VLOOKUP(Prestamos[[#This Row],[ID Libro]],Inventario_Libros!A:B,2,0),"Libro No Existe") -> Rayuela | J20: =IFERROR(VLOOKUP(Prestamos[[#This Row],[ID Libro]],Inventario_Libros!A:C,3,0),"Libro No Existe") -> Julio Cortázar | K20: =IFERROR(VLOOKUP(Prestamos[[#This Row],[ID Libro]],Inventario_Libros!A:D,4,0),"Libro No Existe") -> Novela | L20: =IFERROR(VLOOKUP(Prestamos[[#This Row],[ID Libro]],Inventario_Libros!A:E,5,0),"Libro No Existe") -> 2018 | M20: =_xlfn.XLOOKUP(D:D,Inventario_Libros!A:A,Inventario_Libros!G:G,"No Existe",0) -> B-2 | N20: =IFERROR(VLOOKUP(Prestamos[[#This Row],[ID Libro]],Inventario_Libros!A:H,8,0),"Libro No Existe") -> Retirado
A21: Pr2292 | B21: 45944 | C21: No Asignado | D21: Lb1154 | E21: Ana Gómez | F21: Universidad | G21: Retrasado | H21: 7 | I21: =IFERROR(VLOOKUP(Prestamos[[#This Row],[ID Libro]],Inventario_Libros!A:B,2,0),"Libro No Existe") -> El Código Da Vinci | J21: =IFERROR(VLOOKUP(Prestamos[[#This Row],[ID Libro]],Inventario_Libros!A:C,3,0),"Libro No Existe") -> Dan Brown | K21: =IFERROR(VLOOKUP(Prestamos[[#This Row],[ID Libro]],Inventario_Libros!A:D,4,0),"Libro No Existe") -> Misterio | L21: =IFERROR(VLOOKUP(Prestamos[[#This Row],[ID Libro]],Inventario_Libros!A:E,5,0),"Libro No Existe") -> 1966 | M21: =_xlfn.XLOOKUP(D:D,Inventario_Libros!A:A,Inventario_Libros!G:G,"No Existe",0) -> C-3 | N21: =IFERROR(VLOOKUP(Prestamos[[#This Row],[ID Libro]],Inventario_Libros!A:H,8,0),"Libro No Existe") -> Retirado
A22: Pr2360 | B22: 45944 | C22: 45964 | D22: Lb1160 | E22: Sofía Torres | F22: Estudiante | G22: Retrasado | H22: 5 | I22: =IFERROR(VLOOKUP(Prestamos[[#This Row],[ID Libro]],Inventario_Libros!A:B,2,0),"Libro No Existe") -> Matar A Un Ruiseñor | J22: =IFERROR(VLOOKUP(Prestamos[[#This Row],[ID Libro]],Inventario_Libros!A:C,3,0),"Libro No Existe") -> Harper Lee | K22: =IFERROR(VLOOKUP(Prestamos[[#This Row],[ID Libro]],Inventario_Libros!A:D,4,0),"Libro No Existe") -> Novela | L22: =IFERROR(VLOOKUP(Prestamos[[#This Row],[ID Libro]],Inventario_Libros!A:E,5,0),"Libro No Existe") -> 1967 | M22: =_xlfn.XLOOKUP(D:D,Inventario_Libros!A:A,Inventario_Libros!G:G,"No Existe",0) -> C-3 | N22: =IFERROR(VLOOKUP(Prestamos[[#This Row],[ID Libro]],Inventario_Libros!A:H,8,0),"Libro No Existe") -> Activo
A23: Pr2151 | B23: 45941 | C23: No Asignado | D23: Lb1194 | E23: Camila Álvarez | F23: Adulto | G23: Devuelto | H23: 0 | I23: =IFERROR(VLOOKUP(Prestamos[[#This Row],[ID Libro]],Inventario_Libros!A:B,2,0),"Libro No Existe") -> Cien Años De Soledad | J23: =IFERROR(VLOOKUP(Prestamos[[#This Row],[ID Libro]],Inventario_Libros!A:C,3,0),"Libro No Existe") -> Gabriel García Márquez | K23: =IFERROR(VLOOKUP(Prestamos[[#This Row],[ID Libro]],Inventario_Libros!A:D,4,0),"Libro No Existe") -> Novela | L23: =IFERROR(VLOOKUP(Prestamos[[#This Row],[ID Libro]],Inventario_Libros!A:E,5,0),"Libro No Existe") -> 2014 | M23: =_xlfn.XLOOKUP(D:D,Inventario_Libros!A:A,Inventario_Libros!G:G,"No Existe",0) -> B-2 | N23: =IFERROR(VLOOKUP(Prestamos[[#This Row],[ID Libro]],Inventario_Libros!A:H,8,0),"Libro No Existe") -> Activo
A24: Pr2503 | B24: 45941 | C24: No Asignado | D24: Lb1008 | E24: Valentina Mora | F24: Universidad | G24: Devuelto | H24: 1 | I24: =IFERROR(VLOOKUP(Prestamos[[#This Row],[ID Libro]],Inventario_Libros!A:B,2,0),"Libro No Existe") -> Ficciones | J24: =IFERROR(VLOOKUP(Prestamos[[#This Row],[ID Libro]],Inventario_Libros!A:C,3,0),"Libro No Existe") -> Jorge Luis Borges | K24: =IFERROR(VLOOKUP(Prestamos[[#This Row],[ID Libro]],Inventario_Libros!A:D,4,0),"Libro No Existe") -> Cuentos / Fantasía Metafísica | L24: =IFERROR(VLOOKUP(Prestamos[[#This Row],[ID Libro]],Inventario_Libros!A:E,5,0),"Libro No Existe") -> 1997 | M24: =_xlfn.XLOOKUP(D:D,Inventario_Libros!A:A,Inventario_Libros!G:G,"No Existe",0) -> B-2 | N24: =IFERROR(VLOOKUP(Prestamos[[#This Row],[ID Libro]],Inventario_Libros!A:H,8,0),"Libro No Existe") -> Activo
A25: Pr2527 | B25: 45941 | C25: No Asignado | D25: Lb1076 | E25: Carolina Rojas | F25: Estudiante | G25: Retrasado | H25: 7 | I25: =IFERROR(VLOOKUP(Prestamos[[#This Row],[ID Libro]],Inventario_Libros!A:B,2,0),"Libro No Existe") -> La Tregua | J25: =IFERROR(VLOOKUP(Prestamos[[#This Row],[ID Libro]],Inventario_Libros!A:C,3,0),"Libro No Existe") -> Mario Benedetti | K25: =IFERROR(VLOOKUP(Prestamos[[#This Row],[ID Libro]],Inventario_Libros!A:D,4,0),"Libro No Existe") -> Novela | L25: =IFERROR(VLOOKUP(Prestamos[[#This Row],[ID Libro]],Inventario_Libros!A:E,5,0),"Libro No Existe") -> 1964 | M25: =_xlfn.XLOOKUP(D:D,Inventario_Libros!A:A,Inventario_Libros!G:G,"No Existe",0) -> A-1 | N25: =IFERROR(VLOOKUP(Prestamos[[#This Row],[ID Libro]],Inventario_Libros!A:H,8,0),"Libro No Existe") -> Retirado
A26: Pr2172 | B26: 45936 | C26: No Asignado | D26: Lb1092 | E26: Ana Gómez | F26: Adulto | G26: Devuelto | H26: 1 | I26: =IFERROR(VLOOKUP(Prestamos[[#This Row],[ID Libro]],Inventario_Libros!A:B,2,0),"Libro No Existe") -> La Iliada | J26: =IFERROR(VLOOKUP(Prestamos[[#This Row],[ID Libro]],Inventario_Libros!A:C,3,0),"Libro No Existe") -> Homero | K26: =IFERROR(VLOOKUP(Prestamos[[#This Row],[ID Libro]],Inventario_Libros!A:D,4,0),"Libro No Existe") -> Clásicos | L26: =IFERROR(VLOOKUP(Prestamos[[#This Row],[ID Libro]],Inventario_Libros!A:E,5,0),"Libro No Existe") -> 1996 | M26: =_xlfn.XLOOKUP(D:D,Inventario_Libros!A:A,Inventario_Libros!G:G,"No Existe",0) -> B-2 | N26: =IFERROR(VLOOKUP(Prestamos[[#This Row],[ID Libro]],Inventario_Libros!A:H,8,0),"Libro No Existe") -> Activo
A27: Pr2280 | B27: 45935 | C27: No Asignado | D27: Lb1153 | E27: Jorge Ibáñez | F27: Adulto | G27: Retrasado | H27: 7 | I27: =IFERROR(VLOOKUP(Prestamos[[#This Row],[ID Libro]],Inventario_Libros!A:B,2,0),"Libro No Existe") -> El Aleph | J27: =IFERROR(VLOOKUP(Prestamos[[#This Row],[ID Libro]],Inventario_Libros!A:C,3,0),"Libro No Existe") -> Jorge Luis Borges | K27: =IFERROR(VLOOKUP(Prestamos[[#This Row],[ID Libro]],Inventario_Libros!A:D,4,0),"Libro No Existe") -> Cuentos / Fantasía Metafísica | L27: =IFERROR(VLOOKUP(Prestamos[[#This Row],[ID Libro]],Inventario_Libros!A:E,5,0),"Libro No Existe") -> 1953 | M27: =_xlfn.XLOOKUP(D:D,Inventario_Libros!A:A,Inventario_Libros!G:G,"No Existe",0) -> C-3 | N27: =IFERROR(VLOOKUP(Prestamos[[#This Row],[ID Libro]],Inventario_Libros!A:H,8,0),"Libro No Existe") -> Activo
A28: Pr2566 | B28: 45934 | C28: No Asignado | D28: Lb1070 | E28: Carlos Ruiz | F28: Adulto | G28: Retrasado | H28: 7 | I28: =IFERROR(VLOOKUP(Prestamos[[#This Row],[ID Libro]],Inventario_Libros!A:B,2,0),"Libro No Existe") -> La Iliada | J28: =IFERROR(VLOOKUP(Prestamos[[#This Row],[ID Libro]],Inventario_Libros!A:C,3,0),"Libro No Existe") -> Homero | K28: =IFERROR(VLOOKUP(Prestamos[[#This Row],[ID Libro]],Inventario_Libros!A:D,4,0),"Libro No Existe") -> Clásicos | L28: =IFERROR(VLOOKUP(Prestamos[[#This Row],[ID Libro]],Inventario_Libros!A:E,5,0),"Libro No Existe") -> 1993 | M28: =_xlfn.XLOOKUP(D:D,Inventario_Libros!A:A,Inventario_Libros!G:G,"No Existe",0) -> A-1 | N28: =IFERROR(VLOOKUP(Prestamos[[#This Row],[ID Libro]],Inventario_Libros!A:H,8,0),"Libro No Existe") -> Retirado
A29: Pr2018 | B29: 45932 | C29: No Asignado | D29: Lb1005 | E29: Valentina Mora | F29: Adulto | G29: Devuelto | H29: 1 | I29: =IFERROR(VLOOKUP(Prestamos[[#This Row],[ID Libro]],Inventario_Libros!A:B,2,0),"Libro No Existe") -> Hamlet | J29: =IFERROR(VLOOKUP(Prestamos[[#This Row],[ID Libro]],Inventario_Libros!A:C,3,0),"Libro No Existe") -> William Shakespeare | K29: =IFERROR(VLOOKUP(Prestamos[[#This Row],[ID Libro]],Inventario_Libros!A:D,4,0),"Libro No Existe") -> Clásicos | L29: =IFERROR(VLOOKUP(Prestamos[[#This Row],[ID Libro]],Inventario_Libros!A:E,5,0),"Libro No Existe") -> 1905 | M29: =_xlfn.XLOOKUP(D:D,Inventario_Libros!A:A,Inventario_Libros!G:G,"No Existe",0) -> B-2 | N29: =IFERROR(VLOOKUP(Prestamos[[#This Row],[ID Libro]],Inventario_Libros!A:H,8,0),"Libro No Existe") -> Activo
A30: Pr2142 | B30: 45932 | C30: 45957 | D30: Lb1017 | E30: Luisa Fernández | F30: Niño | G30: Retrasado | H30: 10 | I30: =IFERROR(VLOOKUP(Prestamos[[#This Row],[ID Libro]],Inventario_Libros!A:B,2,0),"Libro No Existe") -> Crónica De Una Muerte Anunciada | J30: =IFERROR(VLOOKUP(Prestamos[[#This Row],[ID Libro]],Inventario_Libros!A:C,3,0),"Libro No Existe") -> Gabriel García Márquez | K30: =IFERROR(VLOOKUP(Prestamos[[#This Row],[ID Libro]],Inventario_Libros!A:D,4,0),"Libro No Existe") -> Novela | L30: =IFERROR(VLOOKUP(Prestamos[[#This Row],[ID Libro]],Inventario_Libros!A:E,5,0),"Libro No Existe") -> 1999 | M30: =_xlfn.XLOOKUP(D:D,Inventario_Libros!A:A,Inventario_Libros!G:G,"No Existe",0) -> A-1 | N30: =IFERROR(VLOOKUP(Prestamos[[#This Row],[ID Libro]],Inventario_Libros!A:H,8,0),"Libro No Existe") -> Activo
A31: Pr2218 | B31: 45929 | C31: No Asignado | D31: Lb1120 | E31: Miguel Ángel | F31: Niño | G31: Devuelto | H31: 1 | I31: =IFERROR(VLOOKUP(Prestamos[[#This Row],[ID Libro]],Inventario_Libros!A:B,2,0),"Libro No Existe") -> Los Detectives Salvajes | J31: =IFERROR(VLOOKUP(Prestamos[[#This Row],[ID Libro]],Inventario_Libros!A:C,3,0),"Libro No Existe") -> Roberto Bolaño | K31: =IFERROR(VLOOKUP(Prestamos[[#This Row],[ID Libro]],Inventario_Libros!A:D,4,0),"Libro No Existe") -> Novela | L31: =IFERROR(VLOOKUP(Prestamos[[#This Row],[ID Libro]],Inventario_Libros!A:E,5,0),"Libro No Existe") -> 1919 | M31: =_xlfn.XLOOKUP(D:D,Inventario_Libros!A:A,Inventario_Libros!G:G,"No Existe",0) -> B-2 | N31: =IFERROR(VLOOKUP(Prestamos[[#This Row],[ID Libro]],Inventario_Libros!A:H,8,0),"Libro No Existe") -> Activo
A32: Pr2451 | B32: 45929 | C32: No Asignado | D32: Lb1162 | E32: Noelia Martín | F32: Niño | G32: Retrasado | H32: 7 | I32: =IFERROR(VLOOKUP(Prestamos[[#This Row],[ID Libro]],Inventario_Libros!A:B,2,0),"Libro No Existe") -> Matar A Un Ruiseñor | J32: =IFERROR(VLOOKUP(Prestamos[[#This Row],[ID Libro]],Inventario_Libros!A:C,3,0),"Libro No Existe") -> Harper Lee | K32: =IFERROR(VLOOKUP(Prestamos[[#This Row],[ID Libro]],Inventario_Libros!A:D,4,0),"Libro No Existe") -> Novela | L32: =IFERROR(VLOOKUP(Prestamos[[#This Row],[ID Libro]],Inventario_Libros!A:E,5,0),"Libro No Existe") -> 1981 | M32: =_xlfn.XLOOKUP(D:D,Inventario_Libros!A:A,Inventario_Libros!G:G,"No Existe",0) -> C-3 | N32: =IFERROR(VLOOKUP(Prestamos[[#This Row],[ID Libro]],Inventario_Libros!A:H,8,0),"Libro No Existe") -> Retirado
A33: Pr2368 | B33: 45925 | C33: No Asignado | D33: Lb1038 | E33: Ana Gómez | F33: Universidad | G33: Retrasado | H33: 7 | I33: =IFERROR(VLOOKUP(Prestamos[[#This Row],[ID Libro]],Inventario_Libros!A:B,2,0),"Libro No Existe") -> La Iliada | J33: =IFERROR(VLOOKUP(Prestamos[[#This Row],[ID Libro]],Inventario_Libros!A:C,3,0),"Libro No Existe") -> Homero | K33: =IFERROR(VLOOKUP(Prestamos[[#This Row],[ID Libro]],Inventario_Libros!A:D,4,0),"Libro No Existe") -> Clásicos | L33: =IFERROR(VLOOKUP(Prestamos[[#This Row],[ID Libro]],Inventario_Libros!A:E,5,0),"Libro No Existe") -> 1940 | M33: =_xlfn.XLOOKUP(D:D,Inventario_Libros!A:A,Inventario_Libros!G:G,"No Existe",0) -> B-2 | N33: =IFERROR(VLOOKUP(Prestamos[[#This Row],[ID Libro]],Inventario_Libros!A:H,8,0),"Libro No Existe") -> Retirado
A34: Pr2040 | B34: 45923 | C34: 45943 | D34: Lb1089 | E34: Juan Pérez | F34: Otros | G34: Retrasado | H34: 5 | I34: =IFERROR(VLOOKUP(Prestamos[[#This Row],[ID Libro]],Inventario_Libros!A:B,2,0),"Libro No Existe") -> Macbeth | J34: =IFERROR(VLOOKUP(Prestamos[[#This Row],[ID Libro]],Inventario_Libros!A:C,3,0),"Libro No Existe") -> William Shakespeare | K34: =IFERROR(VLOOKUP(Prestamos[[#This Row],[ID Libro]],Inventario_Libros!A:D,4,0),"Libro No Existe") -> Clásicos | L34: =IFERROR(VLOOKUP(Prestamos[[#This Row],[ID Libro]],Inventario_Libros!A:E,5,0),"Libro No Existe") -> 1891 | M34: =_xlfn.XLOOKUP(D:D,Inventario_Libros!A:A,Inventario_Libros!G:G,"No Existe",0) -> B-2 | N34: =IFERROR(VLOOKUP(Prestamos[[#This Row],[ID Libro]],Inventario_Libros!A:H,8,0),"Libro No Existe") -> Activo
A35: Pr2495 | B35: 45922 | C35: 45940 | D35: Lb1088 | E35: Carlos Ruiz | F35: Universidad | G35: Retrasado | H35: 3 | I35: =IFERROR(VLOOKUP(Prestamos[[#This Row],[ID Libro]],Inventario_Libros!A:B,2,0),"Libro No Existe") -> Ficciones | J35: =IFERROR(VLOOKUP(Prestamos[[#This Row],[ID Libro]],Inventario_Libros!A:C,3,0),"Libro No Existe") -> Jorge Luis Borges | K35: =IFERROR(VLOOKUP(Prestamos[[#This Row],[ID Libro]],Inventario_Libros!A:D,4,0),"Libro No Existe") -> Cuentos / Fantasía Metafísica | L35: =IFERROR(VLOOKUP(Prestamos[[#This Row],[ID Libro]],Inventario_Libros!A:E,5,0),"Libro No Existe") -> 1939 | M35: =_xlfn.XLOOKUP(D:D,Inventario_Libros!A:A,Inventario_Libros!G:G,"No Existe",0) -> A-1 | N35: =IFERROR(VLOOKUP(Prestamos[[#This Row],[ID Libro]],Inventario_Libros!A:H,8,0),"Libro No Existe") -> Activo
A36: Pr2259 | B36: 45919 | C36: No Asignado | D36: Lb1152 | E36: Juan Pérez | F36: Universidad | G36: Retrasado | H36: 7 | I36: =IFERROR(VLOOKUP(Prestamos[[#This Row],[ID Libro]],Inventario_Libros!A:B,2,0),"Libro No Existe") -> Hamlet | J36: =IFERROR(VLOOKUP(Prestamos[[#This Row],[ID Libro]],Inventario_Libros!A:C,3,0),"Libro No Existe") -> William Shakespeare | K36: =IFERROR(VLOOKUP(Prestamos[[#This Row],[ID Libro]],Inventario_Libros!A:D,4,0),"Libro No Existe") -> Clásicos | L36: =IFERROR(VLOOKUP(Prestamos[[#This Row],[ID Libro]],Inventario_Libros!A:E,5,0),"Libro No Existe") -> 2017 | M36: =_xlfn.XLOOKUP(D:D,Inventario_Libros!A:A,Inventario_Libros!G:G,"No Existe",0) -> A-1 | N36: =IFERROR(VLOOKUP(Prestamos[[#This Row],[ID Libro]],Inventario_Libros!A:H,8,0),"Libro No Existe") -> Activo
A37: Pr2220 | B37: 45912 | C37: 45928 | D37: Lb1178 | E37: Noelia Martín | F37: Niño | G37: Retrasado | H37: 1 | I37: =IFERROR(VLOOKUP(Prestamos[[#This Row],[ID Libro]],Inventario_Libros!A:B,2,0),"Libro No Existe") -> Los Detectives Salvajes | J37: =IFERROR(VLOOKUP(Prestamos[[#This Row],[ID Libro]],Inventario_Libros!A:C,3,0),"Libro No Existe") -> Roberto Bolaño | K37: =IFERROR(VLOOKUP(Prestamos[[#This Row],[ID Libro]],Inventario_Libros!A:D,4,0),"Libro No Existe") -> Novela | L37: =IFERROR(VLOOKUP(Prestamos[[#This Row],[ID Libro]],Inventario_Libros!A:E,5,0),"Libro No Existe") -> 1914 | M37: =_xlfn.XLOOKUP(D:D,Inventario_Libros!A:A,Inventario_Libros!G:G,"No Existe",0) -> C-3 | N37: =IFERROR(VLOOKUP(Prestamos[[#This Row],[ID Libro]],Inventario_Libros!A:H,8,0),"Libro No Existe") -> Retirado
A38: Pr2565 | B38: 45912 | C38: 45932 | D38: Lb1013 | E38: Felipe Ramírez | F38: Estudiante | G38: Retrasado | H38: 5 | I38: =IFERROR(VLOOKUP(Prestamos[[#This Row],[ID Libro]],Inventario_Libros!A:B,2,0),"Libro No Existe") -> La Ciudad Y Los Perros | J38: =IFERROR(VLOOKUP(Prestamos[[#This Row],[ID Libro]],Inventario_Libros!A:C,3,0),"Libro No Existe") -> Mario Vargas Llosa | K38: =IFERROR(VLOOKUP(Prestamos[[#This Row],[ID Libro]],Inventario_Libros!A:D,4,0),"Libro No Existe") -> Novela | L38: =IFERROR(VLOOKUP(Prestamos[[#This Row],[ID Libro]],Inventario_Libros!A:E,5,0),"Libro No Existe") -> 1901 | M38: =_xlfn.XLOOKUP(D:D,Inventario_Libros!A:A,Inventario_Libros!G:G,"No Existe",0) -> Est-1 | N38: =IFERROR(VLOOKUP(Prestamos[[#This Row],[ID Libro]],Inventario_Libros!A:H,8,0),"Libro No Existe") -> Retirado
A39: Pr2376 | B39: 45910 | C39: No Asignado | D39: Lb1185 | E39: Jorge Ibáñez | F39: Otros | G39: Devuelto | H39: 1 | I39: =IFERROR(VLOOKUP(Prestamos[[#This Row],[ID Libro]],Inventario_Libros!A:B,2,0),"Libro No Existe") -> Breve Historia Del Tiempo | J39: =IFERROR(VLOOKUP(Prestamos[[#This Row],[ID Libro]],Inventario_Libros!A:C,3,0),"Libro No Existe") -> Stephen Hawking | K39: =IFERROR(VLOOKUP(Prestamos[[#This Row],[ID Libro]],Inventario_Libros!A:D,4,0),"Libro No Existe") -> Divulgación Científica / Cosmología | L39: =IFERROR(VLOOKUP(Prestamos[[#This Row],[ID Libro]],Inventario_Libros!A:E,5,0),"Libro No Existe") -> 1945 | M39: =_xlfn.XLOOKUP(D:D,Inventario_Libros!A:A,Inventario_Libros!G:G,"No Existe",0) -> C-3 | N39: =IFERROR(VLOOKUP(Prestamos[[#This Row],[ID Libro]],Inventario_Libros!A:H,8,0),"Libro No Existe") -> Retirado
A40: Pr2313 | B40: 45909 | C40: No Asignado | D40: Lb1063 | E40: Pablo López | F40: Universidad | G40: Devuelto | H40: 0 | I40: =IFERROR(VLOOKUP(Prestamos[[#This Row],[ID Libro]],Inventario_Libros!A:B,2,0),"Libro No Existe") -> La Odisea | J40: =IFERROR(VLOOKUP(Prestamos[[#This Row],[ID Libro]],Inventario_Libros!A:C,3,0),"Libro No Existe") -> Homero | K40: =IFERROR(VLOOKUP(Prestamos[[#This Row],[ID Libro]],Inventario_Libros!A:D,4,0),"Libro No Existe") -> Clásicos | L40: =IFERROR(VLOOKUP(Prestamos[[#This Row],[ID Libro]],Inventario_Libros!A:E,5,0),"Libro No Existe") -> 1995 | M40: =_xlfn.XLOOKUP(D:D,Inventario_Libros!A:A,Inventario_Libros!G:G,"No Existe",0) -> Est-1 | N40: =IFERROR(VLOOKUP(Prestamos[[#This Row],[ID Libro]],Inventario_Libros!A:H,8,0),"Libro No Existe") -> Activo
...

Sheet Hoja1
A3: Etiquetas de fila | B3: Cuenta de ID Préstamo
A4: Adulto | B4: 194
A5: Estudiante | B5: 75
A6: Niño | B6: 132
A7: Otros | B7: 58
A8: Universidad | B8: 141
A9: Total general | B9: 600
A21: Etiquetas de fila | B21: Cuenta de ID Préstamo
A22: Devuelto | B22: 220
A23: Pendiente | B23: 120
A24: Retrasado | B24: 260
A25: Total general | B25: 600
A36: Etiquetas de fila | B36: Cuenta de ID Préstamo
A37: Trim.1 | B37: 184
A38: Trim.2 | B38: 140
A39: Trim.3 | B39: 160
A40: Trim.4 | B40: 116
A41: Total general | B41: 600
A55: Cuenta de ID Préstamo
A56: 600
B57: =GETPIVOTDATA("ID Préstamo",$A$55) -> 600

Sheet DashBoard
E1: Dashboard Este Es Un Ejemplo De Como Estructurar Un Panel De Control

Sheet Hoja1 (2)
A1: No Aportes | B1: Razon Social | C1: País | D1: Contacto | E1: Fp | F1: Compañía | G1: Fecha | H1: Aporte | I1: Bono | J1: Total
A2: 10375 | B2: Hungry Coyote Import Store | C2: Estados Unidos | D2: Camilo | E2: cheque | F2: TCC | G2: 41280 | H2: 321.92 | I2: 8.69184 | J2: 330.61184
A3: 10381 | B3: LILA-Supermercado | C3: Venezuela | D3: Camilo | E3: éfectivo | F3: DEPRISA | G3: 41286 | H3: 511.36 | I3: 17.38624 | J3: 528.74624
A4: 10391 | B4: Drachenblut Delikatessen | C4: Alemania | D4: Camilo | E4: éfectivo | F4: DEPRISA | G4: 41297 | H4: 348.8 | I4: 8.3712 | J4: 357.1712
A5: 10410 | B5: Bottom-Dollar Markets | C5: Canadá | D5: Camilo | E5: éfectivo | F5: DEPRISA | G5: 41315 | H5: 153.6 | I5: 5.5296 | J5: 159.1296
A6: 10432 | B6: Split Rail Beer & Ale | C6: Estados Unidos | D6: Camilo | E6: cheque | F6: TCC | G6: 41336 | H6: 277.76 | I6: 7.49952 | J6: 285.25952
A7: 10434 | B7: Folk och fä HB | C7: Suecia | D7: Camilo | E7: cheque | F7: TCC | G7: 41339 | H7: 286.72 | I7: 10.60864 | J7: 297.32864
A8: 10438 | B8: Toms Spezialitäten | C8: Alemania | D8: Camilo | E8: cheque | F8: TCC | G8: 41342 | H8: 527.36 | I8: 12.12928 | J8: 539.48928
A9: 10444 | B9: Berglunds snabbköp | C9: Suecia | D9: Camilo | E9: éfectivo | F9: DEPRISA | G9: 41348 | H9: 224 | I9: 8.512 | J9: 232.512
A10: 10449 | B10: Blondel père et fils | C10: Francia | D10: Camilo | E10: cheque | F10: TCC | G10: 41354 | H10: 852.8 | I10: 16.2032 | J10: 869.0032
A11: 10468 | B11: Königlich Essen | C11: Alemania | D11: Camilo | E11: éfectivo | F11: DEPRISA | G11: 41371 | H11: 705.92 | I11: 16.94208 | J11: 722.86208
A12: 10484 | B12: B's Beverages | C12: Reino Unido | D12: Camilo | E12: éfectivo | F12: DEPRISA | G12: 41388 | H12: 440.32 | I12: 14.09024 | J12: 454.41024
A13: 10495 | B13: Laughing Bacchus Wine Cellars | C13: Canadá | D13: Camilo | E13: éfectivo | F13: DEPRISA | G13: 41398 | H13: 297.6 | I13: 10.7136 | J13: 308.3136
... A168: 11077 | B168: Rattlesnake Canyon Grocery | C168: Estados Unidos | D168: Marcela | E168: cheque | F168: DEPRISA | G168: 41795 | H168: 545.92 | I168: 15.28576 | J168: 561.20576

Sheet Hoja2
A3: Etiquetas de fila | B3: Suma de Total
A4: Alemania | B4: 539.48928
A5: Argentina | B5: 645.34368
A6: Canadá | B6: 731.4552
A7: Estados Unidos | B7: 285.25952
A8: Francia | B8: 1456.9378
A9: Reino Unido | B9: 418.33856
A10: Suecia | B10: 529.84064
A11: Total general | B11: 4606.6646
A28: Etiquetas de fila | B28: Suma de Total
A29: Alemania | B29: 0.1171106
A30: Argentina | B30: 0.14008914
A31: Canadá | B31: 0.15878195
A32: Estados Unidos | B32: 0.061923223
A33: Francia | B33: 0.31626738
A34: Reino Unido | B34: 0.090811594
A35: Suecia | B35: 0.11501611
A36: Total general | B36: 1
A55: Suma de Total | B55: Etiquetas de columna
A56: Etiquetas de fila | B56: cheque | C56: éfectivo | D56: Total general
A57: Camilo | B57: 1991.0806 | C57: 232.512 | D57: 2223.5926
A58: Gladys | B58: 1785.8662 | C58: 178.8672 | D58: 1964.7334
A59: Marcela | B59: 418.33856 | D59: 418.33856
A60: Total general | B60: 4195.2854 | C60: 411.3792 | D60: 4606.6646

Sheet DashBoard (2)
A1: Dashboard Análisis De Datos - Aportes En Dolares
